2025-01-19 19:03:37,482 INFO: Microblog startup [in C:\Users\coolb\Desktop\coding\flasktest\app\__init__.py:34]
2025-01-19 21:20:56,238 INFO: Microblog startup [in C:\Users\coolb\Desktop\coding\flasktest\app\__init__.py:34]
2025-01-19 23:00:25,453 INFO: Microblog startup [in C:\Users\coolb\Desktop\coding\flasktest\app\__init__.py:38]
2025-01-19 23:01:25,275 INFO: Microblog startup [in C:\Users\coolb\Desktop\coding\flasktest\app\__init__.py:38]
2025-01-19 23:08:24,373 INFO: Microblog startup [in C:\Users\coolb\Desktop\coding\flasktest\app\__init__.py:38]
2025-01-19 23:12:22,906 INFO: Microblog startup [in C:\Users\coolb\Desktop\coding\flasktest\app\__init__.py:38]
2025-01-19 23:13:15,579 INFO: Microblog startup [in C:\Users\coolb\Desktop\coding\flasktest\app\__init__.py:38]
2025-01-19 23:24:32,213 INFO: Microblog startup [in C:\Users\coolb\Desktop\coding\flasktest\app\__init__.py:52]
2025-01-19 23:24:45,267 ERROR: Exception on /reset_password_request [POST] [in c:\users\coolb\desktop\coding\flasktest\venv\lib\site-packages\flask\app.py:838]
Traceback (most recent call last):
  File "c:\users\coolb\desktop\coding\flasktest\venv\lib\site-packages\flask\app.py", line 1473, in wsgi_app
    response = self.full_dispatch_request()
  File "c:\users\coolb\desktop\coding\flasktest\venv\lib\site-packages\flask\app.py", line 882, in full_dispatch_request
    rv = self.handle_user_exception(e)
  File "c:\users\coolb\desktop\coding\flasktest\venv\lib\site-packages\flask\app.py", line 880, in full_dispatch_request
    rv = self.dispatch_request()
  File "c:\users\coolb\desktop\coding\flasktest\venv\lib\site-packages\flask\app.py", line 865, in dispatch_request
    return self.ensure_sync(self.view_functions[rule.endpoint])(**view_args)  # type: ignore[no-any-return]
  File "C:\Users\coolb\Desktop\coding\flasktest\app\routes.py", line 176, in reset_password_request
    send_password_reset_email(user)
  File "C:\Users\coolb\Desktop\coding\flasktest\app\email.py", line 13, in send_password_reset_email
    token = user.get_reset_password_token()
  File "C:\Users\coolb\Desktop\coding\flasktest\app\models.py", line 89, in get_reset_password_token
    return jwt.encode(
NameError: name 'jwt' is not defined
2025-01-20 01:02:41,518 INFO: Microblog startup [in C:\Users\coolb\Desktop\coding\flasktest\app\__init__.py:52]
2025-01-20 01:02:50,057 ERROR: Exception on /edit_profile [POST] [in c:\users\coolb\desktop\coding\flasktest\venv\lib\site-packages\flask\app.py:838]
Traceback (most recent call last):
  File "c:\users\coolb\desktop\coding\flasktest\venv\lib\site-packages\sqlalchemy\engine\base.py", line 1964, in _exec_single_context
    self.dialect.do_execute(
  File "c:\users\coolb\desktop\coding\flasktest\venv\lib\site-packages\sqlalchemy\engine\default.py", line 942, in do_execute
    cursor.execute(statement, parameters)
sqlite3.IntegrityError: UNIQUE constraint failed: user.username

The above exception was the direct cause of the following exception:

Traceback (most recent call last):
  File "c:\users\coolb\desktop\coding\flasktest\venv\lib\site-packages\flask\app.py", line 1473, in wsgi_app
    response = self.full_dispatch_request()
  File "c:\users\coolb\desktop\coding\flasktest\venv\lib\site-packages\flask\app.py", line 882, in full_dispatch_request
    rv = self.handle_user_exception(e)
  File "c:\users\coolb\desktop\coding\flasktest\venv\lib\site-packages\flask\app.py", line 880, in full_dispatch_request
    rv = self.dispatch_request()
  File "c:\users\coolb\desktop\coding\flasktest\venv\lib\site-packages\flask\app.py", line 865, in dispatch_request
    return self.ensure_sync(self.view_functions[rule.endpoint])(**view_args)  # type: ignore[no-any-return]
  File "c:\users\coolb\desktop\coding\flasktest\venv\lib\site-packages\flask_login\utils.py", line 290, in decorated_view
    return current_app.ensure_sync(func)(*args, **kwargs)
  File "C:\Users\coolb\Desktop\coding\flasktest\app\routes.py", line 102, in edit_profile
    db.session.commit()
  File "c:\users\coolb\desktop\coding\flasktest\venv\lib\site-packages\sqlalchemy\orm\scoping.py", line 599, in commit
    return self._proxied.commit()
  File "c:\users\coolb\desktop\coding\flasktest\venv\lib\site-packages\sqlalchemy\orm\session.py", line 2032, in commit
    trans.commit(_to_root=True)
  File "<string>", line 2, in commit
  File "c:\users\coolb\desktop\coding\flasktest\venv\lib\site-packages\sqlalchemy\orm\state_changes.py", line 139, in _go
    ret_value = fn(self, *arg, **kw)
  File "c:\users\coolb\desktop\coding\flasktest\venv\lib\site-packages\sqlalchemy\orm\session.py", line 1313, in commit
    self._prepare_impl()
  File "<string>", line 2, in _prepare_impl
  File "c:\users\coolb\desktop\coding\flasktest\venv\lib\site-packages\sqlalchemy\orm\state_changes.py", line 139, in _go
    ret_value = fn(self, *arg, **kw)
  File "c:\users\coolb\desktop\coding\flasktest\venv\lib\site-packages\sqlalchemy\orm\session.py", line 1288, in _prepare_impl
    self.session.flush()
  File "c:\users\coolb\desktop\coding\flasktest\venv\lib\site-packages\sqlalchemy\orm\session.py", line 4353, in flush
    self._flush(objects)
  File "c:\users\coolb\desktop\coding\flasktest\venv\lib\site-packages\sqlalchemy\orm\session.py", line 4489, in _flush
    transaction.rollback(_capture_exception=True)
  File "c:\users\coolb\desktop\coding\flasktest\venv\lib\site-packages\sqlalchemy\util\langhelpers.py", line 146, in __exit__
    raise exc_value.with_traceback(exc_tb)
  File "c:\users\coolb\desktop\coding\flasktest\venv\lib\site-packages\sqlalchemy\orm\session.py", line 4449, in _flush
    flush_context.execute()
  File "c:\users\coolb\desktop\coding\flasktest\venv\lib\site-packages\sqlalchemy\orm\unitofwork.py", line 466, in execute
    rec.execute(self)
  File "c:\users\coolb\desktop\coding\flasktest\venv\lib\site-packages\sqlalchemy\orm\unitofwork.py", line 642, in execute
    util.preloaded.orm_persistence.save_obj(
  File "c:\users\coolb\desktop\coding\flasktest\venv\lib\site-packages\sqlalchemy\orm\persistence.py", line 85, in save_obj
    _emit_update_statements(
  File "c:\users\coolb\desktop\coding\flasktest\venv\lib\site-packages\sqlalchemy\orm\persistence.py", line 912, in _emit_update_statements
    c = connection.execute(
  File "c:\users\coolb\desktop\coding\flasktest\venv\lib\site-packages\sqlalchemy\engine\base.py", line 1416, in execute
    return meth(
  File "c:\users\coolb\desktop\coding\flasktest\venv\lib\site-packages\sqlalchemy\sql\elements.py", line 515, in _execute_on_connection
    return connection._execute_clauseelement(
  File "c:\users\coolb\desktop\coding\flasktest\venv\lib\site-packages\sqlalchemy\engine\base.py", line 1638, in _execute_clauseelement
    ret = self._execute_context(
  File "c:\users\coolb\desktop\coding\flasktest\venv\lib\site-packages\sqlalchemy\engine\base.py", line 1843, in _execute_context
    return self._exec_single_context(
  File "c:\users\coolb\desktop\coding\flasktest\venv\lib\site-packages\sqlalchemy\engine\base.py", line 1983, in _exec_single_context
    self._handle_dbapi_exception(
  File "c:\users\coolb\desktop\coding\flasktest\venv\lib\site-packages\sqlalchemy\engine\base.py", line 2352, in _handle_dbapi_exception
    raise sqlalchemy_exception.with_traceback(exc_info[2]) from e
  File "c:\users\coolb\desktop\coding\flasktest\venv\lib\site-packages\sqlalchemy\engine\base.py", line 1964, in _exec_single_context
    self.dialect.do_execute(
  File "c:\users\coolb\desktop\coding\flasktest\venv\lib\site-packages\sqlalchemy\engine\default.py", line 942, in do_execute
    cursor.execute(statement, parameters)
sqlalchemy.exc.IntegrityError: (sqlite3.IntegrityError) UNIQUE constraint failed: user.username
[SQL: UPDATE user SET username=? WHERE user.id = ?]
[parameters: ('24', 2)]
(Background on this error at: https://sqlalche.me/e/20/gkpj)
2025-01-20 01:36:51,213 INFO: Microblog startup [in C:\Users\coolb\Desktop\coding\flasktest\app\__init__.py:49]
2025-01-20 01:39:20,098 INFO: Microblog startup [in C:\Users\coolb\Desktop\coding\flasktest\app\__init__.py:49]
2025-01-20 01:39:52,118 ERROR: Exception on /reset_password_request [POST] [in c:\users\coolb\desktop\coding\flasktest\venv\lib\site-packages\flask\app.py:838]
Traceback (most recent call last):
  File "c:\users\coolb\desktop\coding\flasktest\venv\lib\site-packages\flask\app.py", line 1473, in wsgi_app
    response = self.full_dispatch_request()
  File "c:\users\coolb\desktop\coding\flasktest\venv\lib\site-packages\flask\app.py", line 882, in full_dispatch_request
    rv = self.handle_user_exception(e)
  File "c:\users\coolb\desktop\coding\flasktest\venv\lib\site-packages\flask\app.py", line 880, in full_dispatch_request
    rv = self.dispatch_request()
  File "c:\users\coolb\desktop\coding\flasktest\venv\lib\site-packages\flask\app.py", line 865, in dispatch_request
    return self.ensure_sync(self.view_functions[rule.endpoint])(**view_args)  # type: ignore[no-any-return]
  File "C:\Users\coolb\Desktop\coding\flasktest\app\routes.py", line 176, in reset_password_request
    send_password_reset_email(user)
  File "C:\Users\coolb\Desktop\coding\flasktest\app\email.py", line 15, in send_password_reset_email
    token = user.get_reset_password_token()
  File "C:\Users\coolb\Desktop\coding\flasktest\app\models.py", line 89, in get_reset_password_token
    return jwt.encode(
NameError: name 'jwt' is not defined
2025-01-20 01:41:43,124 INFO: Microblog startup [in C:\Users\coolb\Desktop\coding\flasktest\app\__init__.py:49]
2025-01-20 01:42:42,200 INFO: Microblog startup [in C:\Users\coolb\Desktop\coding\flasktest\app\__init__.py:49]
2025-01-20 01:43:44,466 INFO: Microblog startup [in C:\Users\coolb\Desktop\coding\flasktest\app\__init__.py:49]
2025-01-20 01:44:32,743 INFO: Microblog startup [in C:\Users\coolb\Desktop\coding\flasktest\app\__init__.py:49]
2025-01-20 01:46:49,856 INFO: Microblog startup [in C:\Users\coolb\Desktop\coding\flasktest\app\__init__.py:49]
2025-01-20 01:50:38,111 INFO: Microblog startup [in C:\Users\coolb\Desktop\coding\flasktest\app\__init__.py:49]
